<?xml version="1.0" ?>
<!--******************************************************************
 ****** File automatically generated by generate_urdf.py script ******
 *********************************************************************-->
<robot xmlns:xacro="http://www.ros.org/wiki/xacro">
	<joint name="LShoulderPitch" type="revolute">
		<parent link="torso"/>
		<child link="LShoulder"/>
		<origin rpy="0 0 0" xyz="0 0.098 0.1"/>
		<axis xyz="0 1.0 0"/>
		<limit effort="1.329" lower="-2.08567" upper="2.08567" velocity="8.26797"/>
	</joint>
	<link name="LShoulder">
		<inertial>
			<mass value="0.09304"/>
			<inertia ixx="1.83025e-05" ixy="2.06011e-06" ixz="1.88776e-09" iyy="1.39005e-05" iyz="-3.66592e-07" izz="2.01862e-05"/>
			<origin rpy="0 0 0" xyz="-0.00165 -0.02663 0.00014"/>
		</inertial>
		<xacro:insert_visu_LShoulder/>
	</link>
	<joint name="LShoulderRoll" type="revolute">
		<parent link="LShoulder"/>
		<child link="LBicep"/>
		<origin rpy="0 0 0" xyz="0 0 0"/>
		<axis xyz="0 0 1.0"/>
		<limit effort="1.7835" lower="-0.314159" upper="1.32645" velocity="7.19407"/>
	</joint>
	<link name="LBicep">
		<inertial>
			<mass value="0.15777"/>
			<inertia ixx="8.7181e-05" ixy="-2.53381e-05" ixz="-1.4213e-05" iyy="0.000274712" iyz="4.71439e-07" izz="0.000241812"/>
			<origin rpy="0 0 0" xyz="0.02455 0.00563 0.0033"/>
		</inertial>
		<xacro:insert_visu_LBicep/>
	</link>
    <!-- left elbow/forarm/wrist/finger joints removed for handless model -->
    <!-- (...) -->
	<joint name="RShoulderPitch" type="revolute">
		<parent link="torso"/>
		<child link="RShoulder"/>
		<origin rpy="0 0 0" xyz="0 -0.098 0.1"/>
		<axis xyz="0 1.0 0"/>
		<limit effort="1.329" lower="-2.08567" upper="2.08567" velocity="8.26797"/>
	</joint>
	<link name="RShoulder">
		<inertial>
			<mass value="0.09304"/>
			<inertia ixx="1.83025e-05" ixy="-2.06011e-06" ixz="1.88776e-09" iyy="1.39005e-05" iyz="3.66592e-07" izz="2.01862e-05"/>
			<origin rpy="0 0 0" xyz="-0.00165 0.02663 0.00014"/>
		</inertial>
		<xacro:insert_visu_RShoulder/>
	</link>
	<joint name="RShoulderRoll" type="revolute">
		<parent link="RShoulder"/>
		<child link="RBicep"/>
		<origin rpy="0 0 0" xyz="0 0 0"/>
		<axis xyz="0 0 1.0"/>
		<limit effort="1.783" lower="-1.32645" upper="0.314159" velocity="7.19407"/>
	</joint>
	<link name="RBicep">
		<inertial>
			<mass value="0.15777"/>
			<inertia ixx="0.000103401" ixy="5.48849e-05" ixz="-1.32643e-05" iyy="0.00027077" iyz="9.16707e-06" izz="0.000254529"/>
			<origin rpy="0 0 0" xyz="0.02455 -0.00563 0.0033"/>
		</inertial>
		<xacro:insert_visu_RBicep/>
	</link>
    <!-- right elbow/forearm/wrist/finger joints removed for handless model -->
    <!-- (...) -->
</robot>
